Num GPUs Available:  0
-- Training set --
Number of pictures: 2855
Number of different labels: 36
Labels: ['lemon' 'peas' 'eggplant' 'cauliflower' 'orange' 'raddish' 'beetroot'
 'lettuce' 'paprika' 'bell pepper' 'garlic' 'grapes' 'pineapple' 'onion'
 'capsicum' 'sweetcorn' 'turnip' 'tomato' 'pomegranate' 'sweetpotato'
 'potato' 'ginger' 'banana' 'kiwi' 'corn' 'chilli pepper' 'soy beans'
 'jalepeno' 'watermelon' 'mango' 'cabbage' 'cucumber' 'pear' 'carrot'
 'apple' 'spinach']
Found 2855 validated image filenames belonging to 36 classes.
Found 340 validated image filenames belonging to 36 classes.
Found 340 validated image filenames belonging to 36 classes.
Epoch 1/15
Traceback (most recent call last):
  File "d:\Politechnika\The Gourmet\Development\modelTraining\network.py", line 149, in <module>
    history = model.fit(
  File "C:\Users\LocalAdmin\AppData\Local\Programs\Python\Python39\lib\site-packages\wandb\integration\keras\keras.py", line 168, in new_v2
    return old_v2(*args, **kwargs)
  File "C:\Users\LocalAdmin\AppData\Local\Programs\Python\Python39\lib\site-packages\keras\utils\traceback_utils.py", line 67, in error_handler
    raise e.with_traceback(filtered_tb) from None
  File "C:\Users\LocalAdmin\AppData\Local\Programs\Python\Python39\lib\site-packages\tensorflow\python\framework\func_graph.py", line 1147, in autograph_handler
    raise e.ag_error_metadata.to_exception(e)
ValueError: in user code:
    File "C:\Users\LocalAdmin\AppData\Local\Programs\Python\Python39\lib\site-packages\keras\engine\training.py", line 1021, in train_function  *
        return step_function(self, iterator)
    File "C:\Users\LocalAdmin\AppData\Local\Programs\Python\Python39\lib\site-packages\keras\engine\training.py", line 1010, in step_function  **
        outputs = model.distribute_strategy.run(run_step, args=(data,))
    File "C:\Users\LocalAdmin\AppData\Local\Programs\Python\Python39\lib\site-packages\keras\engine\training.py", line 1000, in run_step  **
        outputs = model.train_step(data)
    File "C:\Users\LocalAdmin\AppData\Local\Programs\Python\Python39\lib\site-packages\keras\engine\training.py", line 860, in train_step
        loss = self.compute_loss(x, y, y_pred, sample_weight)
    File "C:\Users\LocalAdmin\AppData\Local\Programs\Python\Python39\lib\site-packages\keras\engine\training.py", line 918, in compute_loss
        return self.compiled_loss(
    File "C:\Users\LocalAdmin\AppData\Local\Programs\Python\Python39\lib\site-packages\keras\engine\compile_utils.py", line 201, in __call__
        loss_value = loss_obj(y_t, y_p, sample_weight=sw)
    File "C:\Users\LocalAdmin\AppData\Local\Programs\Python\Python39\lib\site-packages\keras\losses.py", line 141, in __call__
        losses = call_fn(y_true, y_pred)
    File "C:\Users\LocalAdmin\AppData\Local\Programs\Python\Python39\lib\site-packages\keras\losses.py", line 245, in call  **
        return ag_fn(y_true, y_pred, **self._fn_kwargs)
    File "C:\Users\LocalAdmin\AppData\Local\Programs\Python\Python39\lib\site-packages\keras\losses.py", line 1789, in categorical_crossentropy
        return backend.categorical_crossentropy(
    File "C:\Users\LocalAdmin\AppData\Local\Programs\Python\Python39\lib\site-packages\keras\backend.py", line 5083, in categorical_crossentropy
        target.shape.assert_is_compatible_with(output.shape)
    ValueError: Shapes (None, None) and (None, 11, 11, 36) are incompatible