Num GPUs Available:  0
-- Training set --
Number of pictures: 70700
Number of different labels: 101
-- Test set --
Number of pictures: 20200
Number of different labels: 101
-- Validation set --
Number of pictures: 10100
Number of different labels: 101
Labels: ['pad_thai' 'pulled_pork_sandwich' 'greek_salad' 'lasagna' 'seaweed_salad'
 'ceviche' 'beef_tartare' 'spaghetti_bolognese' 'peking_duck' 'hot_dog'
 'foie_gras' 'fried_rice' 'macaroni_and_cheese' 'french_toast'
 'beet_salad' 'ramen' 'bruschetta' 'panna_cotta' 'sushi' 'pancakes'
 'cheese_plate' 'ravioli' 'huevos_rancheros' 'tiramisu' 'baby_back_ribs'
 'fried_calamari' 'garlic_bread' 'steak' 'mussels' 'macarons' 'pizza'
 'cannoli' 'hamburger' 'bibimbap' 'lobster_bisque' 'clam_chowder' 'nachos'
 'chocolate_mousse' 'omelette' 'edamame' 'caprese_salad' 'beef_carpaccio'
 'escargots' 'pork_chop' 'eggs_benedict' 'chicken_wings' 'frozen_yogurt'
 'beignets' 'spring_rolls' 'cup_cakes' 'creme_brulee' 'gyoza'
 'strawberry_shortcake' 'breakfast_burrito' 'ice_cream' 'donuts'
 'prime_rib' 'waffles' 'tuna_tartare' 'french_fries' 'french_onion_soup'
 'caesar_salad' 'takoyaki' 'sashimi' 'gnocchi' 'pho' 'tacos' 'onion_rings'
 'chicken_quesadilla' 'guacamole' 'bread_pudding' 'chicken_curry' 'samosa'
 'miso_soup' 'apple_pie' 'filet_mignon' 'fish_and_chips' 'hummus'
 'shrimp_and_grits' 'cheesecake' 'oysters' 'grilled_salmon' 'dumplings'
 'red_velvet_cake' 'chocolate_cake' 'croque_madame'
 'grilled_cheese_sandwich' 'deviled_eggs' 'baklava' 'crab_cakes'
 'hot_and_sour_soup' 'paella' 'scallops' 'churros' 'falafel'
 'spaghetti_carbonara' 'lobster_roll_sandwich' 'club_sandwich' 'risotto'
 'carrot_cake' 'poutine']
Found 70700 validated image filenames belonging to 101 classes.
Found 10100 validated image filenames belonging to 101 classes.
Found 20200 validated image filenames belonging to 101 classes.
Epoch 1/10
WARNING:tensorflow:`input_shape` is undefined or non-square, or `rows` is not in [96, 128, 160, 192, 224]. Weights for input shape (224, 224) will be loaded as the default.
Traceback (most recent call last):
  File "d:\Politechnika\The Gourmet\Development\modelTraining\network.py", line 156, in <module>
    history = model.fit(
  File "C:\Users\LocalAdmin\AppData\Local\Programs\Python\Python39\lib\site-packages\wandb\integration\keras\keras.py", line 168, in new_v2
    return old_v2(*args, **kwargs)
  File "C:\Users\LocalAdmin\AppData\Local\Programs\Python\Python39\lib\site-packages\keras\utils\traceback_utils.py", line 67, in error_handler
    raise e.with_traceback(filtered_tb) from None
  File "C:\Users\LocalAdmin\AppData\Local\Programs\Python\Python39\lib\site-packages\tensorflow\python\eager\execute.py", line 54, in quick_execute
    tensors = pywrap_tfe.TFE_Py_Execute(ctx._handle, device_name, op_name,
tensorflow.python.framework.errors_impl.InvalidArgumentError: Graph execution error:
Detected at node 'categorical_crossentropy/softmax_cross_entropy_with_logits' defined at (most recent call last):
    File "d:\Politechnika\The Gourmet\Development\modelTraining\network.py", line 156, in <module>
      history = model.fit(
    File "C:\Users\LocalAdmin\AppData\Local\Programs\Python\Python39\lib\site-packages\wandb\integration\keras\keras.py", line 168, in new_v2
      return old_v2(*args, **kwargs)
    File "C:\Users\LocalAdmin\AppData\Local\Programs\Python\Python39\lib\site-packages\keras\utils\traceback_utils.py", line 64, in error_handler
      return fn(*args, **kwargs)
    File "C:\Users\LocalAdmin\AppData\Local\Programs\Python\Python39\lib\site-packages\keras\engine\training.py", line 1384, in fit
      tmp_logs = self.train_function(iterator)
    File "C:\Users\LocalAdmin\AppData\Local\Programs\Python\Python39\lib\site-packages\keras\engine\training.py", line 1021, in train_function
      return step_function(self, iterator)
    File "C:\Users\LocalAdmin\AppData\Local\Programs\Python\Python39\lib\site-packages\keras\engine\training.py", line 1010, in step_function
      outputs = model.distribute_strategy.run(run_step, args=(data,))
    File "C:\Users\LocalAdmin\AppData\Local\Programs\Python\Python39\lib\site-packages\keras\engine\training.py", line 1000, in run_step
      outputs = model.train_step(data)
    File "C:\Users\LocalAdmin\AppData\Local\Programs\Python\Python39\lib\site-packages\keras\engine\training.py", line 860, in train_step
      loss = self.compute_loss(x, y, y_pred, sample_weight)
    File "C:\Users\LocalAdmin\AppData\Local\Programs\Python\Python39\lib\site-packages\keras\engine\training.py", line 918, in compute_loss
      return self.compiled_loss(
    File "C:\Users\LocalAdmin\AppData\Local\Programs\Python\Python39\lib\site-packages\keras\engine\compile_utils.py", line 201, in __call__
      loss_value = loss_obj(y_t, y_p, sample_weight=sw)
    File "C:\Users\LocalAdmin\AppData\Local\Programs\Python\Python39\lib\site-packages\keras\losses.py", line 141, in __call__
      losses = call_fn(y_true, y_pred)
    File "C:\Users\LocalAdmin\AppData\Local\Programs\Python\Python39\lib\site-packages\keras\losses.py", line 245, in call
      return ag_fn(y_true, y_pred, **self._fn_kwargs)
    File "C:\Users\LocalAdmin\AppData\Local\Programs\Python\Python39\lib\site-packages\keras\losses.py", line 1789, in categorical_crossentropy
      return backend.categorical_crossentropy(
    File "C:\Users\LocalAdmin\AppData\Local\Programs\Python\Python39\lib\site-packages\keras\backend.py", line 5098, in categorical_crossentropy
      return tf.nn.softmax_cross_entropy_with_logits(
Node: 'categorical_crossentropy/softmax_cross_entropy_with_logits'
logits and labels must be broadcastable: logits_size=[32,36] labels_size=[32,101]
	 [[{{node categorical_crossentropy/softmax_cross_entropy_with_logits}}]] [Op:__inference_train_function_7538]